[2016-06-14 17:38:32,659] ERROR % : Internal Server Error: /
Traceback (most recent call last):
  File "/home/guinsly/.pyenv/versions/django1.9.3.4.3/lib/python3.4/site-packages/django/db/backends/utils.py", line 64, in execute
    return self.cursor.execute(sql, params)
  File "/home/guinsly/.pyenv/versions/django1.9.3.4.3/lib/python3.4/site-packages/django/db/backends/sqlite3/base.py", line 323, in execute
    return Database.Cursor.execute(self, query, params)
sqlite3.OperationalError: no such table: movies_film

The above exception was the direct cause of the following exception:

Traceback (most recent call last):
  File "/home/guinsly/.pyenv/versions/django1.9.3.4.3/lib/python3.4/site-packages/django/core/handlers/base.py", line 149, in get_response
    response = self.process_exception_by_middleware(e, request)
  File "/home/guinsly/.pyenv/versions/django1.9.3.4.3/lib/python3.4/site-packages/django/core/handlers/base.py", line 147, in get_response
    response = wrapped_callback(request, *callback_args, **callback_kwargs)
  File "/home/guinsly/.pyenv/versions/django1.9.3.4.3/lib/python3.4/site-packages/django/views/generic/base.py", line 68, in view
    return self.dispatch(request, *args, **kwargs)
  File "/home/guinsly/.pyenv/versions/django1.9.3.4.3/lib/python3.4/site-packages/django/views/generic/base.py", line 88, in dispatch
    return handler(request, *args, **kwargs)
  File "/home/guinsly/.pyenv/versions/django1.9.3.4.3/lib/python3.4/site-packages/django/views/generic/list.py", line 174, in get
    context = self.get_context_data()
  File "/tmp/falardeau/applications/movies/views.py", line 23, in get_context_data
    context = super(MoviesListView, self).get_context_data(**kwargs)
  File "/home/guinsly/.pyenv/versions/django1.9.3.4.3/lib/python3.4/site-packages/django/views/generic/list.py", line 134, in get_context_data
    paginator, page, queryset, is_paginated = self.paginate_queryset(queryset, page_size)
  File "/home/guinsly/.pyenv/versions/django1.9.3.4.3/lib/python3.4/site-packages/django/views/generic/list.py", line 78, in paginate_queryset
    page = paginator.page(page_number)
  File "/home/guinsly/.pyenv/versions/django1.9.3.4.3/lib/python3.4/site-packages/django/core/paginator.py", line 50, in page
    number = self.validate_number(number)
  File "/home/guinsly/.pyenv/versions/django1.9.3.4.3/lib/python3.4/site-packages/django/core/paginator.py", line 39, in validate_number
    if number > self.num_pages:
  File "/home/guinsly/.pyenv/versions/django1.9.3.4.3/lib/python3.4/site-packages/django/core/paginator.py", line 86, in _get_num_pages
    if self.count == 0 and not self.allow_empty_first_page:
  File "/home/guinsly/.pyenv/versions/django1.9.3.4.3/lib/python3.4/site-packages/django/core/paginator.py", line 72, in _get_count
    self._count = self.object_list.count()
  File "/home/guinsly/.pyenv/versions/django1.9.3.4.3/lib/python3.4/site-packages/django/db/models/query.py", line 371, in count
    return self.query.get_count(using=self.db)
  File "/home/guinsly/.pyenv/versions/django1.9.3.4.3/lib/python3.4/site-packages/django/db/models/sql/query.py", line 483, in get_count
    number = obj.get_aggregation(using, ['__count'])['__count']
  File "/home/guinsly/.pyenv/versions/django1.9.3.4.3/lib/python3.4/site-packages/django/db/models/sql/query.py", line 464, in get_aggregation
    result = compiler.execute_sql(SINGLE)
  File "/home/guinsly/.pyenv/versions/django1.9.3.4.3/lib/python3.4/site-packages/django/db/models/sql/compiler.py", line 848, in execute_sql
    cursor.execute(sql, params)
  File "/home/guinsly/.pyenv/versions/django1.9.3.4.3/lib/python3.4/site-packages/debug_toolbar/panels/sql/tracking.py", line 159, in execute
    return self._record(self.cursor.execute, sql, params)
  File "/home/guinsly/.pyenv/versions/django1.9.3.4.3/lib/python3.4/site-packages/debug_toolbar/panels/sql/tracking.py", line 101, in _record
    return method(sql, params)
  File "/home/guinsly/.pyenv/versions/django1.9.3.4.3/lib/python3.4/site-packages/django/db/backends/utils.py", line 79, in execute
    return super(CursorDebugWrapper, self).execute(sql, params)
  File "/home/guinsly/.pyenv/versions/django1.9.3.4.3/lib/python3.4/site-packages/django/db/backends/utils.py", line 64, in execute
    return self.cursor.execute(sql, params)
  File "/home/guinsly/.pyenv/versions/django1.9.3.4.3/lib/python3.4/site-packages/django/db/utils.py", line 95, in __exit__
    six.reraise(dj_exc_type, dj_exc_value, traceback)
  File "/home/guinsly/.pyenv/versions/django1.9.3.4.3/lib/python3.4/site-packages/django/utils/six.py", line 685, in reraise
    raise value.with_traceback(tb)
  File "/home/guinsly/.pyenv/versions/django1.9.3.4.3/lib/python3.4/site-packages/django/db/backends/utils.py", line 64, in execute
    return self.cursor.execute(sql, params)
  File "/home/guinsly/.pyenv/versions/django1.9.3.4.3/lib/python3.4/site-packages/django/db/backends/sqlite3/base.py", line 323, in execute
    return Database.Cursor.execute(self, query, params)
django.db.utils.OperationalError: no such table: movies_film
[2016-06-14 17:38:32,988] ERROR % : Internal Server Error: /
Traceback (most recent call last):
  File "/home/guinsly/.pyenv/versions/django1.9.3.4.3/lib/python3.4/site-packages/django/core/handlers/base.py", line 235, in get_response
    response = middleware_method(request, response)
  File "/home/guinsly/.pyenv/versions/django1.9.3.4.3/lib/python3.4/site-packages/debug_toolbar/middleware.py", line 129, in process_response
    panel.generate_stats(request, response)
  File "/home/guinsly/.pyenv/versions/django1.9.3.4.3/lib/python3.4/site-packages/debug_toolbar/panels/staticfiles.py", line 127, in generate_stats
    'staticfiles_finders': self.get_staticfiles_finders(),
  File "/home/guinsly/.pyenv/versions/django1.9.3.4.3/lib/python3.4/site-packages/debug_toolbar/panels/staticfiles.py", line 138, in get_staticfiles_finders
    for path, finder_storage in finder.list([]):
  File "/home/guinsly/.pyenv/versions/django1.9.3.4.3/lib/python3.4/site-packages/django/contrib/staticfiles/finders.py", line 112, in list
    for path in utils.get_files(storage, ignore_patterns):
  File "/home/guinsly/.pyenv/versions/django1.9.3.4.3/lib/python3.4/site-packages/django/contrib/staticfiles/utils.py", line 28, in get_files
    directories, files = storage.listdir(location)
  File "/home/guinsly/.pyenv/versions/django1.9.3.4.3/lib/python3.4/site-packages/django/core/files/storage.py", line 299, in listdir
    for entry in os.listdir(path):
FileNotFoundError: [Errno 2] No such file or directory: '/tmp/falardeau/static'
[2016-06-14 17:38:33,779] WARNING % : Not Found: /favicon.ico
[2016-06-14 17:38:33,837] ERROR % : Internal Server Error: /favicon.ico
Traceback (most recent call last):
  File "/home/guinsly/.pyenv/versions/django1.9.3.4.3/lib/python3.4/site-packages/django/core/handlers/base.py", line 235, in get_response
    response = middleware_method(request, response)
  File "/home/guinsly/.pyenv/versions/django1.9.3.4.3/lib/python3.4/site-packages/debug_toolbar/middleware.py", line 129, in process_response
    panel.generate_stats(request, response)
  File "/home/guinsly/.pyenv/versions/django1.9.3.4.3/lib/python3.4/site-packages/debug_toolbar/panels/staticfiles.py", line 127, in generate_stats
    'staticfiles_finders': self.get_staticfiles_finders(),
  File "/home/guinsly/.pyenv/versions/django1.9.3.4.3/lib/python3.4/site-packages/debug_toolbar/panels/staticfiles.py", line 138, in get_staticfiles_finders
    for path, finder_storage in finder.list([]):
  File "/home/guinsly/.pyenv/versions/django1.9.3.4.3/lib/python3.4/site-packages/django/contrib/staticfiles/finders.py", line 112, in list
    for path in utils.get_files(storage, ignore_patterns):
  File "/home/guinsly/.pyenv/versions/django1.9.3.4.3/lib/python3.4/site-packages/django/contrib/staticfiles/utils.py", line 28, in get_files
    directories, files = storage.listdir(location)
  File "/home/guinsly/.pyenv/versions/django1.9.3.4.3/lib/python3.4/site-packages/django/core/files/storage.py", line 299, in listdir
    for entry in os.listdir(path):
FileNotFoundError: [Errno 2] No such file or directory: '/tmp/falardeau/static'
[2016-06-14 17:38:59,564] ERROR % : Internal Server Error: /
Traceback (most recent call last):
  File "/home/guinsly/.pyenv/versions/django1.9.3.4.3/lib/python3.4/site-packages/django/db/backends/utils.py", line 64, in execute
    return self.cursor.execute(sql, params)
  File "/home/guinsly/.pyenv/versions/django1.9.3.4.3/lib/python3.4/site-packages/django/db/backends/sqlite3/base.py", line 323, in execute
    return Database.Cursor.execute(self, query, params)
sqlite3.OperationalError: no such table: movies_film

The above exception was the direct cause of the following exception:

Traceback (most recent call last):
  File "/home/guinsly/.pyenv/versions/django1.9.3.4.3/lib/python3.4/site-packages/django/core/handlers/base.py", line 149, in get_response
    response = self.process_exception_by_middleware(e, request)
  File "/home/guinsly/.pyenv/versions/django1.9.3.4.3/lib/python3.4/site-packages/django/core/handlers/base.py", line 147, in get_response
    response = wrapped_callback(request, *callback_args, **callback_kwargs)
  File "/home/guinsly/.pyenv/versions/django1.9.3.4.3/lib/python3.4/site-packages/django/views/generic/base.py", line 68, in view
    return self.dispatch(request, *args, **kwargs)
  File "/home/guinsly/.pyenv/versions/django1.9.3.4.3/lib/python3.4/site-packages/django/views/generic/base.py", line 88, in dispatch
    return handler(request, *args, **kwargs)
  File "/home/guinsly/.pyenv/versions/django1.9.3.4.3/lib/python3.4/site-packages/django/views/generic/list.py", line 174, in get
    context = self.get_context_data()
  File "/tmp/falardeau/applications/movies/views.py", line 23, in get_context_data
    context = super(MoviesListView, self).get_context_data(**kwargs)
  File "/home/guinsly/.pyenv/versions/django1.9.3.4.3/lib/python3.4/site-packages/django/views/generic/list.py", line 134, in get_context_data
    paginator, page, queryset, is_paginated = self.paginate_queryset(queryset, page_size)
  File "/home/guinsly/.pyenv/versions/django1.9.3.4.3/lib/python3.4/site-packages/django/views/generic/list.py", line 78, in paginate_queryset
    page = paginator.page(page_number)
  File "/home/guinsly/.pyenv/versions/django1.9.3.4.3/lib/python3.4/site-packages/django/core/paginator.py", line 50, in page
    number = self.validate_number(number)
  File "/home/guinsly/.pyenv/versions/django1.9.3.4.3/lib/python3.4/site-packages/django/core/paginator.py", line 39, in validate_number
    if number > self.num_pages:
  File "/home/guinsly/.pyenv/versions/django1.9.3.4.3/lib/python3.4/site-packages/django/core/paginator.py", line 86, in _get_num_pages
    if self.count == 0 and not self.allow_empty_first_page:
  File "/home/guinsly/.pyenv/versions/django1.9.3.4.3/lib/python3.4/site-packages/django/core/paginator.py", line 72, in _get_count
    self._count = self.object_list.count()
  File "/home/guinsly/.pyenv/versions/django1.9.3.4.3/lib/python3.4/site-packages/django/db/models/query.py", line 371, in count
    return self.query.get_count(using=self.db)
  File "/home/guinsly/.pyenv/versions/django1.9.3.4.3/lib/python3.4/site-packages/django/db/models/sql/query.py", line 483, in get_count
    number = obj.get_aggregation(using, ['__count'])['__count']
  File "/home/guinsly/.pyenv/versions/django1.9.3.4.3/lib/python3.4/site-packages/django/db/models/sql/query.py", line 464, in get_aggregation
    result = compiler.execute_sql(SINGLE)
  File "/home/guinsly/.pyenv/versions/django1.9.3.4.3/lib/python3.4/site-packages/django/db/models/sql/compiler.py", line 848, in execute_sql
    cursor.execute(sql, params)
  File "/home/guinsly/.pyenv/versions/django1.9.3.4.3/lib/python3.4/site-packages/debug_toolbar/panels/sql/tracking.py", line 159, in execute
    return self._record(self.cursor.execute, sql, params)
  File "/home/guinsly/.pyenv/versions/django1.9.3.4.3/lib/python3.4/site-packages/debug_toolbar/panels/sql/tracking.py", line 101, in _record
    return method(sql, params)
  File "/home/guinsly/.pyenv/versions/django1.9.3.4.3/lib/python3.4/site-packages/django/db/backends/utils.py", line 79, in execute
    return super(CursorDebugWrapper, self).execute(sql, params)
  File "/home/guinsly/.pyenv/versions/django1.9.3.4.3/lib/python3.4/site-packages/django/db/backends/utils.py", line 64, in execute
    return self.cursor.execute(sql, params)
  File "/home/guinsly/.pyenv/versions/django1.9.3.4.3/lib/python3.4/site-packages/django/db/utils.py", line 95, in __exit__
    six.reraise(dj_exc_type, dj_exc_value, traceback)
  File "/home/guinsly/.pyenv/versions/django1.9.3.4.3/lib/python3.4/site-packages/django/utils/six.py", line 685, in reraise
    raise value.with_traceback(tb)
  File "/home/guinsly/.pyenv/versions/django1.9.3.4.3/lib/python3.4/site-packages/django/db/backends/utils.py", line 64, in execute
    return self.cursor.execute(sql, params)
  File "/home/guinsly/.pyenv/versions/django1.9.3.4.3/lib/python3.4/site-packages/django/db/backends/sqlite3/base.py", line 323, in execute
    return Database.Cursor.execute(self, query, params)
django.db.utils.OperationalError: no such table: movies_film
[2016-06-14 17:39:00,658] WARNING % : Not Found: /favicon.ico
