[2016-06-14 17:38:32,659] ERROR % : Internal Server Error: /
Traceback (most recent call last):
  File "/home/guinsly/.pyenv/versions/django1.9.3.4.3/lib/python3.4/site-packages/django/db/backends/utils.py", line 64, in execute
    return self.cursor.execute(sql, params)
  File "/home/guinsly/.pyenv/versions/django1.9.3.4.3/lib/python3.4/site-packages/django/db/backends/sqlite3/base.py", line 323, in execute
    return Database.Cursor.execute(self, query, params)
sqlite3.OperationalError: no such table: movies_film

The above exception was the direct cause of the following exception:

Traceback (most recent call last):
  File "/home/guinsly/.pyenv/versions/django1.9.3.4.3/lib/python3.4/site-packages/django/core/handlers/base.py", line 149, in get_response
    response = self.process_exception_by_middleware(e, request)
  File "/home/guinsly/.pyenv/versions/django1.9.3.4.3/lib/python3.4/site-packages/django/core/handlers/base.py", line 147, in get_response
    response = wrapped_callback(request, *callback_args, **callback_kwargs)
  File "/home/guinsly/.pyenv/versions/django1.9.3.4.3/lib/python3.4/site-packages/django/views/generic/base.py", line 68, in view
    return self.dispatch(request, *args, **kwargs)
  File "/home/guinsly/.pyenv/versions/django1.9.3.4.3/lib/python3.4/site-packages/django/views/generic/base.py", line 88, in dispatch
    return handler(request, *args, **kwargs)
  File "/home/guinsly/.pyenv/versions/django1.9.3.4.3/lib/python3.4/site-packages/django/views/generic/list.py", line 174, in get
    context = self.get_context_data()
  File "/tmp/falardeau/applications/movies/views.py", line 23, in get_context_data
    context = super(MoviesListView, self).get_context_data(**kwargs)
  File "/home/guinsly/.pyenv/versions/django1.9.3.4.3/lib/python3.4/site-packages/django/views/generic/list.py", line 134, in get_context_data
    paginator, page, queryset, is_paginated = self.paginate_queryset(queryset, page_size)
  File "/home/guinsly/.pyenv/versions/django1.9.3.4.3/lib/python3.4/site-packages/django/views/generic/list.py", line 78, in paginate_queryset
    page = paginator.page(page_number)
  File "/home/guinsly/.pyenv/versions/django1.9.3.4.3/lib/python3.4/site-packages/django/core/paginator.py", line 50, in page
    number = self.validate_number(number)
  File "/home/guinsly/.pyenv/versions/django1.9.3.4.3/lib/python3.4/site-packages/django/core/paginator.py", line 39, in validate_number
    if number > self.num_pages:
  File "/home/guinsly/.pyenv/versions/django1.9.3.4.3/lib/python3.4/site-packages/django/core/paginator.py", line 86, in _get_num_pages
    if self.count == 0 and not self.allow_empty_first_page:
  File "/home/guinsly/.pyenv/versions/django1.9.3.4.3/lib/python3.4/site-packages/django/core/paginator.py", line 72, in _get_count
    self._count = self.object_list.count()
  File "/home/guinsly/.pyenv/versions/django1.9.3.4.3/lib/python3.4/site-packages/django/db/models/query.py", line 371, in count
    return self.query.get_count(using=self.db)
  File "/home/guinsly/.pyenv/versions/django1.9.3.4.3/lib/python3.4/site-packages/django/db/models/sql/query.py", line 483, in get_count
    number = obj.get_aggregation(using, ['__count'])['__count']
  File "/home/guinsly/.pyenv/versions/django1.9.3.4.3/lib/python3.4/site-packages/django/db/models/sql/query.py", line 464, in get_aggregation
    result = compiler.execute_sql(SINGLE)
  File "/home/guinsly/.pyenv/versions/django1.9.3.4.3/lib/python3.4/site-packages/django/db/models/sql/compiler.py", line 848, in execute_sql
    cursor.execute(sql, params)
  File "/home/guinsly/.pyenv/versions/django1.9.3.4.3/lib/python3.4/site-packages/debug_toolbar/panels/sql/tracking.py", line 159, in execute
    return self._record(self.cursor.execute, sql, params)
  File "/home/guinsly/.pyenv/versions/django1.9.3.4.3/lib/python3.4/site-packages/debug_toolbar/panels/sql/tracking.py", line 101, in _record
    return method(sql, params)
  File "/home/guinsly/.pyenv/versions/django1.9.3.4.3/lib/python3.4/site-packages/django/db/backends/utils.py", line 79, in execute
    return super(CursorDebugWrapper, self).execute(sql, params)
  File "/home/guinsly/.pyenv/versions/django1.9.3.4.3/lib/python3.4/site-packages/django/db/backends/utils.py", line 64, in execute
    return self.cursor.execute(sql, params)
  File "/home/guinsly/.pyenv/versions/django1.9.3.4.3/lib/python3.4/site-packages/django/db/utils.py", line 95, in __exit__
    six.reraise(dj_exc_type, dj_exc_value, traceback)
  File "/home/guinsly/.pyenv/versions/django1.9.3.4.3/lib/python3.4/site-packages/django/utils/six.py", line 685, in reraise
    raise value.with_traceback(tb)
  File "/home/guinsly/.pyenv/versions/django1.9.3.4.3/lib/python3.4/site-packages/django/db/backends/utils.py", line 64, in execute
    return self.cursor.execute(sql, params)
  File "/home/guinsly/.pyenv/versions/django1.9.3.4.3/lib/python3.4/site-packages/django/db/backends/sqlite3/base.py", line 323, in execute
    return Database.Cursor.execute(self, query, params)
django.db.utils.OperationalError: no such table: movies_film
[2016-06-14 17:38:32,988] ERROR % : Internal Server Error: /
Traceback (most recent call last):
  File "/home/guinsly/.pyenv/versions/django1.9.3.4.3/lib/python3.4/site-packages/django/core/handlers/base.py", line 235, in get_response
    response = middleware_method(request, response)
  File "/home/guinsly/.pyenv/versions/django1.9.3.4.3/lib/python3.4/site-packages/debug_toolbar/middleware.py", line 129, in process_response
    panel.generate_stats(request, response)
  File "/home/guinsly/.pyenv/versions/django1.9.3.4.3/lib/python3.4/site-packages/debug_toolbar/panels/staticfiles.py", line 127, in generate_stats
    'staticfiles_finders': self.get_staticfiles_finders(),
  File "/home/guinsly/.pyenv/versions/django1.9.3.4.3/lib/python3.4/site-packages/debug_toolbar/panels/staticfiles.py", line 138, in get_staticfiles_finders
    for path, finder_storage in finder.list([]):
  File "/home/guinsly/.pyenv/versions/django1.9.3.4.3/lib/python3.4/site-packages/django/contrib/staticfiles/finders.py", line 112, in list
    for path in utils.get_files(storage, ignore_patterns):
  File "/home/guinsly/.pyenv/versions/django1.9.3.4.3/lib/python3.4/site-packages/django/contrib/staticfiles/utils.py", line 28, in get_files
    directories, files = storage.listdir(location)
  File "/home/guinsly/.pyenv/versions/django1.9.3.4.3/lib/python3.4/site-packages/django/core/files/storage.py", line 299, in listdir
    for entry in os.listdir(path):
FileNotFoundError: [Errno 2] No such file or directory: '/tmp/falardeau/static'
[2016-06-14 17:38:33,779] WARNING % : Not Found: /favicon.ico
[2016-06-14 17:38:33,837] ERROR % : Internal Server Error: /favicon.ico
Traceback (most recent call last):
  File "/home/guinsly/.pyenv/versions/django1.9.3.4.3/lib/python3.4/site-packages/django/core/handlers/base.py", line 235, in get_response
    response = middleware_method(request, response)
  File "/home/guinsly/.pyenv/versions/django1.9.3.4.3/lib/python3.4/site-packages/debug_toolbar/middleware.py", line 129, in process_response
    panel.generate_stats(request, response)
  File "/home/guinsly/.pyenv/versions/django1.9.3.4.3/lib/python3.4/site-packages/debug_toolbar/panels/staticfiles.py", line 127, in generate_stats
    'staticfiles_finders': self.get_staticfiles_finders(),
  File "/home/guinsly/.pyenv/versions/django1.9.3.4.3/lib/python3.4/site-packages/debug_toolbar/panels/staticfiles.py", line 138, in get_staticfiles_finders
    for path, finder_storage in finder.list([]):
  File "/home/guinsly/.pyenv/versions/django1.9.3.4.3/lib/python3.4/site-packages/django/contrib/staticfiles/finders.py", line 112, in list
    for path in utils.get_files(storage, ignore_patterns):
  File "/home/guinsly/.pyenv/versions/django1.9.3.4.3/lib/python3.4/site-packages/django/contrib/staticfiles/utils.py", line 28, in get_files
    directories, files = storage.listdir(location)
  File "/home/guinsly/.pyenv/versions/django1.9.3.4.3/lib/python3.4/site-packages/django/core/files/storage.py", line 299, in listdir
    for entry in os.listdir(path):
FileNotFoundError: [Errno 2] No such file or directory: '/tmp/falardeau/static'
[2016-06-14 17:38:59,564] ERROR % : Internal Server Error: /
Traceback (most recent call last):
  File "/home/guinsly/.pyenv/versions/django1.9.3.4.3/lib/python3.4/site-packages/django/db/backends/utils.py", line 64, in execute
    return self.cursor.execute(sql, params)
  File "/home/guinsly/.pyenv/versions/django1.9.3.4.3/lib/python3.4/site-packages/django/db/backends/sqlite3/base.py", line 323, in execute
    return Database.Cursor.execute(self, query, params)
sqlite3.OperationalError: no such table: movies_film

The above exception was the direct cause of the following exception:

Traceback (most recent call last):
  File "/home/guinsly/.pyenv/versions/django1.9.3.4.3/lib/python3.4/site-packages/django/core/handlers/base.py", line 149, in get_response
    response = self.process_exception_by_middleware(e, request)
  File "/home/guinsly/.pyenv/versions/django1.9.3.4.3/lib/python3.4/site-packages/django/core/handlers/base.py", line 147, in get_response
    response = wrapped_callback(request, *callback_args, **callback_kwargs)
  File "/home/guinsly/.pyenv/versions/django1.9.3.4.3/lib/python3.4/site-packages/django/views/generic/base.py", line 68, in view
    return self.dispatch(request, *args, **kwargs)
  File "/home/guinsly/.pyenv/versions/django1.9.3.4.3/lib/python3.4/site-packages/django/views/generic/base.py", line 88, in dispatch
    return handler(request, *args, **kwargs)
  File "/home/guinsly/.pyenv/versions/django1.9.3.4.3/lib/python3.4/site-packages/django/views/generic/list.py", line 174, in get
    context = self.get_context_data()
  File "/tmp/falardeau/applications/movies/views.py", line 23, in get_context_data
    context = super(MoviesListView, self).get_context_data(**kwargs)
  File "/home/guinsly/.pyenv/versions/django1.9.3.4.3/lib/python3.4/site-packages/django/views/generic/list.py", line 134, in get_context_data
    paginator, page, queryset, is_paginated = self.paginate_queryset(queryset, page_size)
  File "/home/guinsly/.pyenv/versions/django1.9.3.4.3/lib/python3.4/site-packages/django/views/generic/list.py", line 78, in paginate_queryset
    page = paginator.page(page_number)
  File "/home/guinsly/.pyenv/versions/django1.9.3.4.3/lib/python3.4/site-packages/django/core/paginator.py", line 50, in page
    number = self.validate_number(number)
  File "/home/guinsly/.pyenv/versions/django1.9.3.4.3/lib/python3.4/site-packages/django/core/paginator.py", line 39, in validate_number
    if number > self.num_pages:
  File "/home/guinsly/.pyenv/versions/django1.9.3.4.3/lib/python3.4/site-packages/django/core/paginator.py", line 86, in _get_num_pages
    if self.count == 0 and not self.allow_empty_first_page:
  File "/home/guinsly/.pyenv/versions/django1.9.3.4.3/lib/python3.4/site-packages/django/core/paginator.py", line 72, in _get_count
    self._count = self.object_list.count()
  File "/home/guinsly/.pyenv/versions/django1.9.3.4.3/lib/python3.4/site-packages/django/db/models/query.py", line 371, in count
    return self.query.get_count(using=self.db)
  File "/home/guinsly/.pyenv/versions/django1.9.3.4.3/lib/python3.4/site-packages/django/db/models/sql/query.py", line 483, in get_count
    number = obj.get_aggregation(using, ['__count'])['__count']
  File "/home/guinsly/.pyenv/versions/django1.9.3.4.3/lib/python3.4/site-packages/django/db/models/sql/query.py", line 464, in get_aggregation
    result = compiler.execute_sql(SINGLE)
  File "/home/guinsly/.pyenv/versions/django1.9.3.4.3/lib/python3.4/site-packages/django/db/models/sql/compiler.py", line 848, in execute_sql
    cursor.execute(sql, params)
  File "/home/guinsly/.pyenv/versions/django1.9.3.4.3/lib/python3.4/site-packages/debug_toolbar/panels/sql/tracking.py", line 159, in execute
    return self._record(self.cursor.execute, sql, params)
  File "/home/guinsly/.pyenv/versions/django1.9.3.4.3/lib/python3.4/site-packages/debug_toolbar/panels/sql/tracking.py", line 101, in _record
    return method(sql, params)
  File "/home/guinsly/.pyenv/versions/django1.9.3.4.3/lib/python3.4/site-packages/django/db/backends/utils.py", line 79, in execute
    return super(CursorDebugWrapper, self).execute(sql, params)
  File "/home/guinsly/.pyenv/versions/django1.9.3.4.3/lib/python3.4/site-packages/django/db/backends/utils.py", line 64, in execute
    return self.cursor.execute(sql, params)
  File "/home/guinsly/.pyenv/versions/django1.9.3.4.3/lib/python3.4/site-packages/django/db/utils.py", line 95, in __exit__
    six.reraise(dj_exc_type, dj_exc_value, traceback)
  File "/home/guinsly/.pyenv/versions/django1.9.3.4.3/lib/python3.4/site-packages/django/utils/six.py", line 685, in reraise
    raise value.with_traceback(tb)
  File "/home/guinsly/.pyenv/versions/django1.9.3.4.3/lib/python3.4/site-packages/django/db/backends/utils.py", line 64, in execute
    return self.cursor.execute(sql, params)
  File "/home/guinsly/.pyenv/versions/django1.9.3.4.3/lib/python3.4/site-packages/django/db/backends/sqlite3/base.py", line 323, in execute
    return Database.Cursor.execute(self, query, params)
django.db.utils.OperationalError: no such table: movies_film
[2016-06-14 17:39:00,658] WARNING % : Not Found: /favicon.ico
[2016-06-14 17:40:53,736] WARNING % : Not Found: /account/login
[2016-06-14 17:41:12,218] ERROR % : Internal Server Error: /accounts/dropbox/login/
Traceback (most recent call last):
  File "/home/guinsly/.pyenv/versions/django1.9.3.4.3/lib/python3.4/site-packages/django/core/handlers/base.py", line 149, in get_response
    response = self.process_exception_by_middleware(e, request)
  File "/home/guinsly/.pyenv/versions/django1.9.3.4.3/lib/python3.4/site-packages/django/core/handlers/base.py", line 147, in get_response
    response = wrapped_callback(request, *callback_args, **callback_kwargs)
  File "/home/guinsly/.pyenv/versions/django1.9.3.4.3/lib/python3.4/site-packages/allauth/socialaccount/providers/oauth/views.py", line 34, in view
    return self.dispatch(request, *args, **kwargs)
  File "/home/guinsly/.pyenv/versions/django1.9.3.4.3/lib/python3.4/site-packages/allauth/socialaccount/providers/oauth/views.py", line 61, in dispatch
    client = self._get_client(request, callback_url)
  File "/home/guinsly/.pyenv/versions/django1.9.3.4.3/lib/python3.4/site-packages/allauth/socialaccount/providers/oauth/views.py", line 39, in _get_client
    app = provider.get_app(request)
  File "/home/guinsly/.pyenv/versions/django1.9.3.4.3/lib/python3.4/site-packages/allauth/socialaccount/providers/base.py", line 38, in get_app
    return SocialApp.objects.get_current(self.id, request)
  File "/home/guinsly/.pyenv/versions/django1.9.3.4.3/lib/python3.4/site-packages/allauth/socialaccount/models.py", line 31, in get_current
    provider=provider)
  File "/home/guinsly/.pyenv/versions/django1.9.3.4.3/lib/python3.4/site-packages/django/db/models/manager.py", line 122, in manager_method
    return getattr(self.get_queryset(), name)(*args, **kwargs)
  File "/home/guinsly/.pyenv/versions/django1.9.3.4.3/lib/python3.4/site-packages/django/db/models/query.py", line 387, in get
    self.model._meta.object_name
allauth.socialaccount.models.DoesNotExist: SocialApp matching query does not exist.
[2016-06-14 18:25:07,479] WARNING % : Not Found: /account/login
[2016-06-14 18:34:20,322] ERROR % : Internal Server Error: /account/login/
Traceback (most recent call last):
  File "/home/guinsly/.pyenv/versions/django1.9.3.4.3/lib/python3.4/site-packages/django/core/handlers/base.py", line 132, in get_response
    response = wrapped_callback(request, *callback_args, **callback_kwargs)
  File "/tmp/falardeau/applications/account/views.py", line 25, in user_login
    return render(request, 'login.html', {'form':form})
  File "/home/guinsly/.pyenv/versions/django1.9.3.4.3/lib/python3.4/site-packages/django/shortcuts.py", line 67, in render
    template_name, context, request=request, using=using)
  File "/home/guinsly/.pyenv/versions/django1.9.3.4.3/lib/python3.4/site-packages/django/template/loader.py", line 98, in render_to_string
    template = get_template(template_name, using=using)
  File "/home/guinsly/.pyenv/versions/django1.9.3.4.3/lib/python3.4/site-packages/django/template/loader.py", line 46, in get_template
    raise TemplateDoesNotExist(template_name)
django.template.base.TemplateDoesNotExist: login.html
[2016-06-14 18:40:04,381] ERROR % : Internal Server Error: /account/login/
Traceback (most recent call last):
  File "/home/guinsly/.pyenv/versions/django1.9.3.4.3/lib/python3.4/site-packages/django/template/defaulttags.py", line 501, in render
    current_app=current_app)
  File "/home/guinsly/.pyenv/versions/django1.9.3.4.3/lib/python3.4/site-packages/django/core/urlresolvers.py", line 578, in reverse
    return force_text(iri_to_uri(resolver._reverse_with_prefix(view, prefix, *args, **kwargs)))
  File "/home/guinsly/.pyenv/versions/django1.9.3.4.3/lib/python3.4/site-packages/django/core/urlresolvers.py", line 495, in _reverse_with_prefix
    (lookup_view_s, args, kwargs, len(patterns), patterns))
django.core.urlresolvers.NoReverseMatch: Reverse for 'settings.register' with arguments '()' and keyword arguments '{}' not found. 0 pattern(s) tried: []

During handling of the above exception, another exception occurred:

Traceback (most recent call last):
  File "/home/guinsly/.pyenv/versions/django1.9.3.4.3/lib/python3.4/site-packages/django/core/handlers/base.py", line 164, in get_response
    response = response.render()
  File "/home/guinsly/.pyenv/versions/django1.9.3.4.3/lib/python3.4/site-packages/django/template/response.py", line 158, in render
    self.content = self.rendered_content
  File "/home/guinsly/.pyenv/versions/django1.9.3.4.3/lib/python3.4/site-packages/django/template/response.py", line 135, in rendered_content
    content = template.render(context, self._request)
  File "/home/guinsly/.pyenv/versions/django1.9.3.4.3/lib/python3.4/site-packages/django/template/backends/django.py", line 74, in render
    return self.template.render(context)
  File "/home/guinsly/.pyenv/versions/django1.9.3.4.3/lib/python3.4/site-packages/django/template/base.py", line 210, in render
    return self._render(context)
  File "/home/guinsly/.pyenv/versions/django1.9.3.4.3/lib/python3.4/site-packages/django/test/utils.py", line 96, in instrumented_test_render
    return self.nodelist.render(context)
  File "/home/guinsly/.pyenv/versions/django1.9.3.4.3/lib/python3.4/site-packages/django/template/base.py", line 905, in render
    bit = self.render_node(node, context)
  File "/home/guinsly/.pyenv/versions/django1.9.3.4.3/lib/python3.4/site-packages/django/template/debug.py", line 79, in render_node
    return node.render(context)
  File "/home/guinsly/.pyenv/versions/django1.9.3.4.3/lib/python3.4/site-packages/django/template/loader_tags.py", line 135, in render
    return compiled_parent._render(context)
  File "/home/guinsly/.pyenv/versions/django1.9.3.4.3/lib/python3.4/site-packages/django/test/utils.py", line 96, in instrumented_test_render
    return self.nodelist.render(context)
  File "/home/guinsly/.pyenv/versions/django1.9.3.4.3/lib/python3.4/site-packages/django/template/base.py", line 905, in render
    bit = self.render_node(node, context)
  File "/home/guinsly/.pyenv/versions/django1.9.3.4.3/lib/python3.4/site-packages/django/template/debug.py", line 79, in render_node
    return node.render(context)
  File "/home/guinsly/.pyenv/versions/django1.9.3.4.3/lib/python3.4/site-packages/django/template/loader_tags.py", line 65, in render
    result = block.nodelist.render(context)
  File "/home/guinsly/.pyenv/versions/django1.9.3.4.3/lib/python3.4/site-packages/django/template/base.py", line 905, in render
    bit = self.render_node(node, context)
  File "/home/guinsly/.pyenv/versions/django1.9.3.4.3/lib/python3.4/site-packages/django/template/debug.py", line 79, in render_node
    return node.render(context)
  File "/home/guinsly/.pyenv/versions/django1.9.3.4.3/lib/python3.4/site-packages/django/template/defaulttags.py", line 329, in render
    return nodelist.render(context)
  File "/home/guinsly/.pyenv/versions/django1.9.3.4.3/lib/python3.4/site-packages/django/template/base.py", line 905, in render
    bit = self.render_node(node, context)
  File "/home/guinsly/.pyenv/versions/django1.9.3.4.3/lib/python3.4/site-packages/django/template/debug.py", line 79, in render_node
    return node.render(context)
  File "/home/guinsly/.pyenv/versions/django1.9.3.4.3/lib/python3.4/site-packages/django/template/defaulttags.py", line 507, in render
    six.reraise(*exc_info)
  File "/home/guinsly/.pyenv/versions/django1.9.3.4.3/lib/python3.4/site-packages/django/utils/six.py", line 686, in reraise
    raise value
  File "/home/guinsly/.pyenv/versions/django1.9.3.4.3/lib/python3.4/site-packages/django/template/defaulttags.py", line 493, in render
    url = reverse(view_name, args=args, kwargs=kwargs, current_app=current_app)
  File "/home/guinsly/.pyenv/versions/django1.9.3.4.3/lib/python3.4/site-packages/django/core/urlresolvers.py", line 578, in reverse
    return force_text(iri_to_uri(resolver._reverse_with_prefix(view, prefix, *args, **kwargs)))
  File "/home/guinsly/.pyenv/versions/django1.9.3.4.3/lib/python3.4/site-packages/django/core/urlresolvers.py", line 495, in _reverse_with_prefix
    (lookup_view_s, args, kwargs, len(patterns), patterns))
django.core.urlresolvers.NoReverseMatch: Reverse for 'register' with arguments '()' and keyword arguments '{}' not found. 0 pattern(s) tried: []
[2016-06-14 18:47:40,246] ERROR % : Internal Server Error: /account/login/
Traceback (most recent call last):
  File "/home/guinsly/.pyenv/versions/django1.9.3.4.3/lib/python3.4/site-packages/django/template/defaulttags.py", line 501, in render
    current_app=current_app)
  File "/home/guinsly/.pyenv/versions/django1.9.3.4.3/lib/python3.4/site-packages/django/core/urlresolvers.py", line 578, in reverse
    return force_text(iri_to_uri(resolver._reverse_with_prefix(view, prefix, *args, **kwargs)))
  File "/home/guinsly/.pyenv/versions/django1.9.3.4.3/lib/python3.4/site-packages/django/core/urlresolvers.py", line 495, in _reverse_with_prefix
    (lookup_view_s, args, kwargs, len(patterns), patterns))
django.core.urlresolvers.NoReverseMatch: Reverse for 'settings.login' with arguments '()' and keyword arguments '{}' not found. 0 pattern(s) tried: []

During handling of the above exception, another exception occurred:

Traceback (most recent call last):
  File "/home/guinsly/.pyenv/versions/django1.9.3.4.3/lib/python3.4/site-packages/django/core/handlers/base.py", line 164, in get_response
    response = response.render()
  File "/home/guinsly/.pyenv/versions/django1.9.3.4.3/lib/python3.4/site-packages/django/template/response.py", line 158, in render
    self.content = self.rendered_content
  File "/home/guinsly/.pyenv/versions/django1.9.3.4.3/lib/python3.4/site-packages/django/template/response.py", line 135, in rendered_content
    content = template.render(context, self._request)
  File "/home/guinsly/.pyenv/versions/django1.9.3.4.3/lib/python3.4/site-packages/django/template/backends/django.py", line 74, in render
    return self.template.render(context)
  File "/home/guinsly/.pyenv/versions/django1.9.3.4.3/lib/python3.4/site-packages/django/template/base.py", line 210, in render
    return self._render(context)
  File "/home/guinsly/.pyenv/versions/django1.9.3.4.3/lib/python3.4/site-packages/django/test/utils.py", line 96, in instrumented_test_render
    return self.nodelist.render(context)
  File "/home/guinsly/.pyenv/versions/django1.9.3.4.3/lib/python3.4/site-packages/django/template/base.py", line 905, in render
    bit = self.render_node(node, context)
  File "/home/guinsly/.pyenv/versions/django1.9.3.4.3/lib/python3.4/site-packages/django/template/debug.py", line 79, in render_node
    return node.render(context)
  File "/home/guinsly/.pyenv/versions/django1.9.3.4.3/lib/python3.4/site-packages/django/template/loader_tags.py", line 135, in render
    return compiled_parent._render(context)
  File "/home/guinsly/.pyenv/versions/django1.9.3.4.3/lib/python3.4/site-packages/django/test/utils.py", line 96, in instrumented_test_render
    return self.nodelist.render(context)
  File "/home/guinsly/.pyenv/versions/django1.9.3.4.3/lib/python3.4/site-packages/django/template/base.py", line 905, in render
    bit = self.render_node(node, context)
  File "/home/guinsly/.pyenv/versions/django1.9.3.4.3/lib/python3.4/site-packages/django/template/debug.py", line 79, in render_node
    return node.render(context)
  File "/home/guinsly/.pyenv/versions/django1.9.3.4.3/lib/python3.4/site-packages/django/template/defaulttags.py", line 329, in render
    return nodelist.render(context)
  File "/home/guinsly/.pyenv/versions/django1.9.3.4.3/lib/python3.4/site-packages/django/template/base.py", line 905, in render
    bit = self.render_node(node, context)
  File "/home/guinsly/.pyenv/versions/django1.9.3.4.3/lib/python3.4/site-packages/django/template/debug.py", line 79, in render_node
    return node.render(context)
  File "/home/guinsly/.pyenv/versions/django1.9.3.4.3/lib/python3.4/site-packages/django/template/defaulttags.py", line 507, in render
    six.reraise(*exc_info)
  File "/home/guinsly/.pyenv/versions/django1.9.3.4.3/lib/python3.4/site-packages/django/utils/six.py", line 686, in reraise
    raise value
  File "/home/guinsly/.pyenv/versions/django1.9.3.4.3/lib/python3.4/site-packages/django/template/defaulttags.py", line 493, in render
    url = reverse(view_name, args=args, kwargs=kwargs, current_app=current_app)
  File "/home/guinsly/.pyenv/versions/django1.9.3.4.3/lib/python3.4/site-packages/django/core/urlresolvers.py", line 578, in reverse
    return force_text(iri_to_uri(resolver._reverse_with_prefix(view, prefix, *args, **kwargs)))
  File "/home/guinsly/.pyenv/versions/django1.9.3.4.3/lib/python3.4/site-packages/django/core/urlresolvers.py", line 495, in _reverse_with_prefix
    (lookup_view_s, args, kwargs, len(patterns), patterns))
django.core.urlresolvers.NoReverseMatch: Reverse for 'login' with arguments '()' and keyword arguments '{}' not found. 0 pattern(s) tried: []
[2016-06-14 18:52:31,660] ERROR % : Internal Server Error: /account/login/
Traceback (most recent call last):
  File "/home/guinsly/.pyenv/versions/django1.9.3.4.3/lib/python3.4/site-packages/django/template/defaulttags.py", line 501, in render
    current_app=current_app)
  File "/home/guinsly/.pyenv/versions/django1.9.3.4.3/lib/python3.4/site-packages/django/core/urlresolvers.py", line 578, in reverse
    return force_text(iri_to_uri(resolver._reverse_with_prefix(view, prefix, *args, **kwargs)))
  File "/home/guinsly/.pyenv/versions/django1.9.3.4.3/lib/python3.4/site-packages/django/core/urlresolvers.py", line 495, in _reverse_with_prefix
    (lookup_view_s, args, kwargs, len(patterns), patterns))
django.core.urlresolvers.NoReverseMatch: Reverse for 'settings.login' with arguments '()' and keyword arguments '{}' not found. 0 pattern(s) tried: []

During handling of the above exception, another exception occurred:

Traceback (most recent call last):
  File "/home/guinsly/.pyenv/versions/django1.9.3.4.3/lib/python3.4/site-packages/django/core/handlers/base.py", line 164, in get_response
    response = response.render()
  File "/home/guinsly/.pyenv/versions/django1.9.3.4.3/lib/python3.4/site-packages/django/template/response.py", line 158, in render
    self.content = self.rendered_content
  File "/home/guinsly/.pyenv/versions/django1.9.3.4.3/lib/python3.4/site-packages/django/template/response.py", line 135, in rendered_content
    content = template.render(context, self._request)
  File "/home/guinsly/.pyenv/versions/django1.9.3.4.3/lib/python3.4/site-packages/django/template/backends/django.py", line 74, in render
    return self.template.render(context)
  File "/home/guinsly/.pyenv/versions/django1.9.3.4.3/lib/python3.4/site-packages/django/template/base.py", line 210, in render
    return self._render(context)
  File "/home/guinsly/.pyenv/versions/django1.9.3.4.3/lib/python3.4/site-packages/django/test/utils.py", line 96, in instrumented_test_render
    return self.nodelist.render(context)
  File "/home/guinsly/.pyenv/versions/django1.9.3.4.3/lib/python3.4/site-packages/django/template/base.py", line 905, in render
    bit = self.render_node(node, context)
  File "/home/guinsly/.pyenv/versions/django1.9.3.4.3/lib/python3.4/site-packages/django/template/debug.py", line 79, in render_node
    return node.render(context)
  File "/home/guinsly/.pyenv/versions/django1.9.3.4.3/lib/python3.4/site-packages/django/template/loader_tags.py", line 135, in render
    return compiled_parent._render(context)
  File "/home/guinsly/.pyenv/versions/django1.9.3.4.3/lib/python3.4/site-packages/django/test/utils.py", line 96, in instrumented_test_render
    return self.nodelist.render(context)
  File "/home/guinsly/.pyenv/versions/django1.9.3.4.3/lib/python3.4/site-packages/django/template/base.py", line 905, in render
    bit = self.render_node(node, context)
  File "/home/guinsly/.pyenv/versions/django1.9.3.4.3/lib/python3.4/site-packages/django/template/debug.py", line 79, in render_node
    return node.render(context)
  File "/home/guinsly/.pyenv/versions/django1.9.3.4.3/lib/python3.4/site-packages/django/template/defaulttags.py", line 329, in render
    return nodelist.render(context)
  File "/home/guinsly/.pyenv/versions/django1.9.3.4.3/lib/python3.4/site-packages/django/template/base.py", line 905, in render
    bit = self.render_node(node, context)
  File "/home/guinsly/.pyenv/versions/django1.9.3.4.3/lib/python3.4/site-packages/django/template/debug.py", line 79, in render_node
    return node.render(context)
  File "/home/guinsly/.pyenv/versions/django1.9.3.4.3/lib/python3.4/site-packages/django/template/defaulttags.py", line 507, in render
    six.reraise(*exc_info)
  File "/home/guinsly/.pyenv/versions/django1.9.3.4.3/lib/python3.4/site-packages/django/utils/six.py", line 686, in reraise
    raise value
  File "/home/guinsly/.pyenv/versions/django1.9.3.4.3/lib/python3.4/site-packages/django/template/defaulttags.py", line 493, in render
    url = reverse(view_name, args=args, kwargs=kwargs, current_app=current_app)
  File "/home/guinsly/.pyenv/versions/django1.9.3.4.3/lib/python3.4/site-packages/django/core/urlresolvers.py", line 578, in reverse
    return force_text(iri_to_uri(resolver._reverse_with_prefix(view, prefix, *args, **kwargs)))
  File "/home/guinsly/.pyenv/versions/django1.9.3.4.3/lib/python3.4/site-packages/django/core/urlresolvers.py", line 495, in _reverse_with_prefix
    (lookup_view_s, args, kwargs, len(patterns), patterns))
django.core.urlresolvers.NoReverseMatch: Reverse for 'login' with arguments '()' and keyword arguments '{}' not found. 0 pattern(s) tried: []
[2016-06-14 18:52:51,519] ERROR % : Internal Server Error: /account/login/
Traceback (most recent call last):
  File "/home/guinsly/.pyenv/versions/django1.9.3.4.3/lib/python3.4/site-packages/django/template/defaulttags.py", line 501, in render
    current_app=current_app)
  File "/home/guinsly/.pyenv/versions/django1.9.3.4.3/lib/python3.4/site-packages/django/core/urlresolvers.py", line 578, in reverse
    return force_text(iri_to_uri(resolver._reverse_with_prefix(view, prefix, *args, **kwargs)))
  File "/home/guinsly/.pyenv/versions/django1.9.3.4.3/lib/python3.4/site-packages/django/core/urlresolvers.py", line 495, in _reverse_with_prefix
    (lookup_view_s, args, kwargs, len(patterns), patterns))
django.core.urlresolvers.NoReverseMatch: Reverse for 'settings.login' with arguments '()' and keyword arguments '{}' not found. 0 pattern(s) tried: []

During handling of the above exception, another exception occurred:

Traceback (most recent call last):
  File "/home/guinsly/.pyenv/versions/django1.9.3.4.3/lib/python3.4/site-packages/django/core/handlers/base.py", line 164, in get_response
    response = response.render()
  File "/home/guinsly/.pyenv/versions/django1.9.3.4.3/lib/python3.4/site-packages/django/template/response.py", line 158, in render
    self.content = self.rendered_content
  File "/home/guinsly/.pyenv/versions/django1.9.3.4.3/lib/python3.4/site-packages/django/template/response.py", line 135, in rendered_content
    content = template.render(context, self._request)
  File "/home/guinsly/.pyenv/versions/django1.9.3.4.3/lib/python3.4/site-packages/django/template/backends/django.py", line 74, in render
    return self.template.render(context)
  File "/home/guinsly/.pyenv/versions/django1.9.3.4.3/lib/python3.4/site-packages/django/template/base.py", line 210, in render
    return self._render(context)
  File "/home/guinsly/.pyenv/versions/django1.9.3.4.3/lib/python3.4/site-packages/django/test/utils.py", line 96, in instrumented_test_render
    return self.nodelist.render(context)
  File "/home/guinsly/.pyenv/versions/django1.9.3.4.3/lib/python3.4/site-packages/django/template/base.py", line 905, in render
    bit = self.render_node(node, context)
  File "/home/guinsly/.pyenv/versions/django1.9.3.4.3/lib/python3.4/site-packages/django/template/debug.py", line 79, in render_node
    return node.render(context)
  File "/home/guinsly/.pyenv/versions/django1.9.3.4.3/lib/python3.4/site-packages/django/template/loader_tags.py", line 135, in render
    return compiled_parent._render(context)
  File "/home/guinsly/.pyenv/versions/django1.9.3.4.3/lib/python3.4/site-packages/django/test/utils.py", line 96, in instrumented_test_render
    return self.nodelist.render(context)
  File "/home/guinsly/.pyenv/versions/django1.9.3.4.3/lib/python3.4/site-packages/django/template/base.py", line 905, in render
    bit = self.render_node(node, context)
  File "/home/guinsly/.pyenv/versions/django1.9.3.4.3/lib/python3.4/site-packages/django/template/debug.py", line 79, in render_node
    return node.render(context)
  File "/home/guinsly/.pyenv/versions/django1.9.3.4.3/lib/python3.4/site-packages/django/template/defaulttags.py", line 329, in render
    return nodelist.render(context)
  File "/home/guinsly/.pyenv/versions/django1.9.3.4.3/lib/python3.4/site-packages/django/template/base.py", line 905, in render
    bit = self.render_node(node, context)
  File "/home/guinsly/.pyenv/versions/django1.9.3.4.3/lib/python3.4/site-packages/django/template/debug.py", line 79, in render_node
    return node.render(context)
  File "/home/guinsly/.pyenv/versions/django1.9.3.4.3/lib/python3.4/site-packages/django/template/defaulttags.py", line 507, in render
    six.reraise(*exc_info)
  File "/home/guinsly/.pyenv/versions/django1.9.3.4.3/lib/python3.4/site-packages/django/utils/six.py", line 686, in reraise
    raise value
  File "/home/guinsly/.pyenv/versions/django1.9.3.4.3/lib/python3.4/site-packages/django/template/defaulttags.py", line 493, in render
    url = reverse(view_name, args=args, kwargs=kwargs, current_app=current_app)
  File "/home/guinsly/.pyenv/versions/django1.9.3.4.3/lib/python3.4/site-packages/django/core/urlresolvers.py", line 578, in reverse
    return force_text(iri_to_uri(resolver._reverse_with_prefix(view, prefix, *args, **kwargs)))
  File "/home/guinsly/.pyenv/versions/django1.9.3.4.3/lib/python3.4/site-packages/django/core/urlresolvers.py", line 495, in _reverse_with_prefix
    (lookup_view_s, args, kwargs, len(patterns), patterns))
django.core.urlresolvers.NoReverseMatch: Reverse for 'login' with arguments '()' and keyword arguments '{}' not found. 0 pattern(s) tried: []
[2016-06-14 18:56:34,673] WARNING % : Not Found: /accounts/login/
[2016-06-14 18:56:37,825] WARNING % : Not Found: /accounts/login/
[2016-06-14 18:56:46,805] WARNING % : Not Found: /accounts/login/
[2016-06-14 18:57:09,108] ERROR % : Internal Server Error: /account/login/
Traceback (most recent call last):
  File "/home/guinsly/.pyenv/versions/django1.9.3.4.3/lib/python3.4/site-packages/django/template/defaulttags.py", line 501, in render
    current_app=current_app)
  File "/home/guinsly/.pyenv/versions/django1.9.3.4.3/lib/python3.4/site-packages/django/core/urlresolvers.py", line 578, in reverse
    return force_text(iri_to_uri(resolver._reverse_with_prefix(view, prefix, *args, **kwargs)))
  File "/home/guinsly/.pyenv/versions/django1.9.3.4.3/lib/python3.4/site-packages/django/core/urlresolvers.py", line 495, in _reverse_with_prefix
    (lookup_view_s, args, kwargs, len(patterns), patterns))
django.core.urlresolvers.NoReverseMatch: Reverse for 'settings.login' with arguments '()' and keyword arguments '{}' not found. 0 pattern(s) tried: []

During handling of the above exception, another exception occurred:

Traceback (most recent call last):
  File "/home/guinsly/.pyenv/versions/django1.9.3.4.3/lib/python3.4/site-packages/django/core/handlers/base.py", line 164, in get_response
    response = response.render()
  File "/home/guinsly/.pyenv/versions/django1.9.3.4.3/lib/python3.4/site-packages/django/template/response.py", line 158, in render
    self.content = self.rendered_content
  File "/home/guinsly/.pyenv/versions/django1.9.3.4.3/lib/python3.4/site-packages/django/template/response.py", line 135, in rendered_content
    content = template.render(context, self._request)
  File "/home/guinsly/.pyenv/versions/django1.9.3.4.3/lib/python3.4/site-packages/django/template/backends/django.py", line 74, in render
    return self.template.render(context)
  File "/home/guinsly/.pyenv/versions/django1.9.3.4.3/lib/python3.4/site-packages/django/template/base.py", line 210, in render
    return self._render(context)
  File "/home/guinsly/.pyenv/versions/django1.9.3.4.3/lib/python3.4/site-packages/django/test/utils.py", line 96, in instrumented_test_render
    return self.nodelist.render(context)
  File "/home/guinsly/.pyenv/versions/django1.9.3.4.3/lib/python3.4/site-packages/django/template/base.py", line 905, in render
    bit = self.render_node(node, context)
  File "/home/guinsly/.pyenv/versions/django1.9.3.4.3/lib/python3.4/site-packages/django/template/debug.py", line 79, in render_node
    return node.render(context)
  File "/home/guinsly/.pyenv/versions/django1.9.3.4.3/lib/python3.4/site-packages/django/template/loader_tags.py", line 135, in render
    return compiled_parent._render(context)
  File "/home/guinsly/.pyenv/versions/django1.9.3.4.3/lib/python3.4/site-packages/django/test/utils.py", line 96, in instrumented_test_render
    return self.nodelist.render(context)
  File "/home/guinsly/.pyenv/versions/django1.9.3.4.3/lib/python3.4/site-packages/django/template/base.py", line 905, in render
    bit = self.render_node(node, context)
  File "/home/guinsly/.pyenv/versions/django1.9.3.4.3/lib/python3.4/site-packages/django/template/debug.py", line 79, in render_node
    return node.render(context)
  File "/home/guinsly/.pyenv/versions/django1.9.3.4.3/lib/python3.4/site-packages/django/template/defaulttags.py", line 329, in render
    return nodelist.render(context)
  File "/home/guinsly/.pyenv/versions/django1.9.3.4.3/lib/python3.4/site-packages/django/template/base.py", line 905, in render
    bit = self.render_node(node, context)
  File "/home/guinsly/.pyenv/versions/django1.9.3.4.3/lib/python3.4/site-packages/django/template/debug.py", line 79, in render_node
    return node.render(context)
  File "/home/guinsly/.pyenv/versions/django1.9.3.4.3/lib/python3.4/site-packages/django/template/defaulttags.py", line 507, in render
    six.reraise(*exc_info)
  File "/home/guinsly/.pyenv/versions/django1.9.3.4.3/lib/python3.4/site-packages/django/utils/six.py", line 686, in reraise
    raise value
  File "/home/guinsly/.pyenv/versions/django1.9.3.4.3/lib/python3.4/site-packages/django/template/defaulttags.py", line 493, in render
    url = reverse(view_name, args=args, kwargs=kwargs, current_app=current_app)
  File "/home/guinsly/.pyenv/versions/django1.9.3.4.3/lib/python3.4/site-packages/django/core/urlresolvers.py", line 578, in reverse
    return force_text(iri_to_uri(resolver._reverse_with_prefix(view, prefix, *args, **kwargs)))
  File "/home/guinsly/.pyenv/versions/django1.9.3.4.3/lib/python3.4/site-packages/django/core/urlresolvers.py", line 495, in _reverse_with_prefix
    (lookup_view_s, args, kwargs, len(patterns), patterns))
django.core.urlresolvers.NoReverseMatch: Reverse for 'login' with arguments '()' and keyword arguments '{}' not found. 0 pattern(s) tried: []
[2016-06-14 19:04:08,351] ERROR % : Internal Server Error: /account/login/
Traceback (most recent call last):
  File "/home/guinsly/.pyenv/versions/django1.9.3.4.3/lib/python3.4/site-packages/django/template/defaulttags.py", line 501, in render
    current_app=current_app)
  File "/home/guinsly/.pyenv/versions/django1.9.3.4.3/lib/python3.4/site-packages/django/core/urlresolvers.py", line 578, in reverse
    return force_text(iri_to_uri(resolver._reverse_with_prefix(view, prefix, *args, **kwargs)))
  File "/home/guinsly/.pyenv/versions/django1.9.3.4.3/lib/python3.4/site-packages/django/core/urlresolvers.py", line 495, in _reverse_with_prefix
    (lookup_view_s, args, kwargs, len(patterns), patterns))
django.core.urlresolvers.NoReverseMatch: Reverse for 'settings.login' with arguments '()' and keyword arguments '{}' not found. 0 pattern(s) tried: []

During handling of the above exception, another exception occurred:

Traceback (most recent call last):
  File "/home/guinsly/.pyenv/versions/django1.9.3.4.3/lib/python3.4/site-packages/django/core/handlers/base.py", line 164, in get_response
    response = response.render()
  File "/home/guinsly/.pyenv/versions/django1.9.3.4.3/lib/python3.4/site-packages/django/template/response.py", line 158, in render
    self.content = self.rendered_content
  File "/home/guinsly/.pyenv/versions/django1.9.3.4.3/lib/python3.4/site-packages/django/template/response.py", line 135, in rendered_content
    content = template.render(context, self._request)
  File "/home/guinsly/.pyenv/versions/django1.9.3.4.3/lib/python3.4/site-packages/django/template/backends/django.py", line 74, in render
    return self.template.render(context)
  File "/home/guinsly/.pyenv/versions/django1.9.3.4.3/lib/python3.4/site-packages/django/template/base.py", line 210, in render
    return self._render(context)
  File "/home/guinsly/.pyenv/versions/django1.9.3.4.3/lib/python3.4/site-packages/django/test/utils.py", line 96, in instrumented_test_render
    return self.nodelist.render(context)
  File "/home/guinsly/.pyenv/versions/django1.9.3.4.3/lib/python3.4/site-packages/django/template/base.py", line 905, in render
    bit = self.render_node(node, context)
  File "/home/guinsly/.pyenv/versions/django1.9.3.4.3/lib/python3.4/site-packages/django/template/debug.py", line 79, in render_node
    return node.render(context)
  File "/home/guinsly/.pyenv/versions/django1.9.3.4.3/lib/python3.4/site-packages/django/template/loader_tags.py", line 135, in render
    return compiled_parent._render(context)
  File "/home/guinsly/.pyenv/versions/django1.9.3.4.3/lib/python3.4/site-packages/django/test/utils.py", line 96, in instrumented_test_render
    return self.nodelist.render(context)
  File "/home/guinsly/.pyenv/versions/django1.9.3.4.3/lib/python3.4/site-packages/django/template/base.py", line 905, in render
    bit = self.render_node(node, context)
  File "/home/guinsly/.pyenv/versions/django1.9.3.4.3/lib/python3.4/site-packages/django/template/debug.py", line 79, in render_node
    return node.render(context)
  File "/home/guinsly/.pyenv/versions/django1.9.3.4.3/lib/python3.4/site-packages/django/template/defaulttags.py", line 329, in render
    return nodelist.render(context)
  File "/home/guinsly/.pyenv/versions/django1.9.3.4.3/lib/python3.4/site-packages/django/template/base.py", line 905, in render
    bit = self.render_node(node, context)
  File "/home/guinsly/.pyenv/versions/django1.9.3.4.3/lib/python3.4/site-packages/django/template/debug.py", line 79, in render_node
    return node.render(context)
  File "/home/guinsly/.pyenv/versions/django1.9.3.4.3/lib/python3.4/site-packages/django/template/defaulttags.py", line 507, in render
    six.reraise(*exc_info)
  File "/home/guinsly/.pyenv/versions/django1.9.3.4.3/lib/python3.4/site-packages/django/utils/six.py", line 686, in reraise
    raise value
  File "/home/guinsly/.pyenv/versions/django1.9.3.4.3/lib/python3.4/site-packages/django/template/defaulttags.py", line 493, in render
    url = reverse(view_name, args=args, kwargs=kwargs, current_app=current_app)
  File "/home/guinsly/.pyenv/versions/django1.9.3.4.3/lib/python3.4/site-packages/django/core/urlresolvers.py", line 578, in reverse
    return force_text(iri_to_uri(resolver._reverse_with_prefix(view, prefix, *args, **kwargs)))
  File "/home/guinsly/.pyenv/versions/django1.9.3.4.3/lib/python3.4/site-packages/django/core/urlresolvers.py", line 495, in _reverse_with_prefix
    (lookup_view_s, args, kwargs, len(patterns), patterns))
django.core.urlresolvers.NoReverseMatch: Reverse for 'login' with arguments '()' and keyword arguments '{}' not found. 0 pattern(s) tried: []
[2016-06-14 19:05:09,963] ERROR % : Internal Server Error: /account/login/
Traceback (most recent call last):
  File "/home/guinsly/.pyenv/versions/django1.9.3.4.3/lib/python3.4/site-packages/django/template/defaulttags.py", line 501, in render
    current_app=current_app)
  File "/home/guinsly/.pyenv/versions/django1.9.3.4.3/lib/python3.4/site-packages/django/core/urlresolvers.py", line 578, in reverse
    return force_text(iri_to_uri(resolver._reverse_with_prefix(view, prefix, *args, **kwargs)))
  File "/home/guinsly/.pyenv/versions/django1.9.3.4.3/lib/python3.4/site-packages/django/core/urlresolvers.py", line 495, in _reverse_with_prefix
    (lookup_view_s, args, kwargs, len(patterns), patterns))
django.core.urlresolvers.NoReverseMatch: Reverse for 'settings.login' with arguments '()' and keyword arguments '{}' not found. 0 pattern(s) tried: []

During handling of the above exception, another exception occurred:

Traceback (most recent call last):
  File "/home/guinsly/.pyenv/versions/django1.9.3.4.3/lib/python3.4/site-packages/django/core/handlers/base.py", line 164, in get_response
    response = response.render()
  File "/home/guinsly/.pyenv/versions/django1.9.3.4.3/lib/python3.4/site-packages/django/template/response.py", line 158, in render
    self.content = self.rendered_content
  File "/home/guinsly/.pyenv/versions/django1.9.3.4.3/lib/python3.4/site-packages/django/template/response.py", line 135, in rendered_content
    content = template.render(context, self._request)
  File "/home/guinsly/.pyenv/versions/django1.9.3.4.3/lib/python3.4/site-packages/django/template/backends/django.py", line 74, in render
    return self.template.render(context)
  File "/home/guinsly/.pyenv/versions/django1.9.3.4.3/lib/python3.4/site-packages/django/template/base.py", line 210, in render
    return self._render(context)
  File "/home/guinsly/.pyenv/versions/django1.9.3.4.3/lib/python3.4/site-packages/django/test/utils.py", line 96, in instrumented_test_render
    return self.nodelist.render(context)
  File "/home/guinsly/.pyenv/versions/django1.9.3.4.3/lib/python3.4/site-packages/django/template/base.py", line 905, in render
    bit = self.render_node(node, context)
  File "/home/guinsly/.pyenv/versions/django1.9.3.4.3/lib/python3.4/site-packages/django/template/debug.py", line 79, in render_node
    return node.render(context)
  File "/home/guinsly/.pyenv/versions/django1.9.3.4.3/lib/python3.4/site-packages/django/template/loader_tags.py", line 135, in render
    return compiled_parent._render(context)
  File "/home/guinsly/.pyenv/versions/django1.9.3.4.3/lib/python3.4/site-packages/django/test/utils.py", line 96, in instrumented_test_render
    return self.nodelist.render(context)
  File "/home/guinsly/.pyenv/versions/django1.9.3.4.3/lib/python3.4/site-packages/django/template/base.py", line 905, in render
    bit = self.render_node(node, context)
  File "/home/guinsly/.pyenv/versions/django1.9.3.4.3/lib/python3.4/site-packages/django/template/debug.py", line 79, in render_node
    return node.render(context)
  File "/home/guinsly/.pyenv/versions/django1.9.3.4.3/lib/python3.4/site-packages/django/template/defaulttags.py", line 329, in render
    return nodelist.render(context)
  File "/home/guinsly/.pyenv/versions/django1.9.3.4.3/lib/python3.4/site-packages/django/template/base.py", line 905, in render
    bit = self.render_node(node, context)
  File "/home/guinsly/.pyenv/versions/django1.9.3.4.3/lib/python3.4/site-packages/django/template/debug.py", line 79, in render_node
    return node.render(context)
  File "/home/guinsly/.pyenv/versions/django1.9.3.4.3/lib/python3.4/site-packages/django/template/defaulttags.py", line 507, in render
    six.reraise(*exc_info)
  File "/home/guinsly/.pyenv/versions/django1.9.3.4.3/lib/python3.4/site-packages/django/utils/six.py", line 686, in reraise
    raise value
  File "/home/guinsly/.pyenv/versions/django1.9.3.4.3/lib/python3.4/site-packages/django/template/defaulttags.py", line 493, in render
    url = reverse(view_name, args=args, kwargs=kwargs, current_app=current_app)
  File "/home/guinsly/.pyenv/versions/django1.9.3.4.3/lib/python3.4/site-packages/django/core/urlresolvers.py", line 578, in reverse
    return force_text(iri_to_uri(resolver._reverse_with_prefix(view, prefix, *args, **kwargs)))
  File "/home/guinsly/.pyenv/versions/django1.9.3.4.3/lib/python3.4/site-packages/django/core/urlresolvers.py", line 495, in _reverse_with_prefix
    (lookup_view_s, args, kwargs, len(patterns), patterns))
django.core.urlresolvers.NoReverseMatch: Reverse for 'login' with arguments '()' and keyword arguments '{}' not found. 0 pattern(s) tried: []
[2016-06-14 19:05:30,510] ERROR % : Internal Server Error: /account/login/
Traceback (most recent call last):
  File "/home/guinsly/.pyenv/versions/django1.9.3.4.3/lib/python3.4/site-packages/django/template/defaulttags.py", line 501, in render
    current_app=current_app)
  File "/home/guinsly/.pyenv/versions/django1.9.3.4.3/lib/python3.4/site-packages/django/core/urlresolvers.py", line 578, in reverse
    return force_text(iri_to_uri(resolver._reverse_with_prefix(view, prefix, *args, **kwargs)))
  File "/home/guinsly/.pyenv/versions/django1.9.3.4.3/lib/python3.4/site-packages/django/core/urlresolvers.py", line 495, in _reverse_with_prefix
    (lookup_view_s, args, kwargs, len(patterns), patterns))
django.core.urlresolvers.NoReverseMatch: Reverse for 'settings.register' with arguments '()' and keyword arguments '{}' not found. 0 pattern(s) tried: []

During handling of the above exception, another exception occurred:

Traceback (most recent call last):
  File "/home/guinsly/.pyenv/versions/django1.9.3.4.3/lib/python3.4/site-packages/django/core/handlers/base.py", line 164, in get_response
    response = response.render()
  File "/home/guinsly/.pyenv/versions/django1.9.3.4.3/lib/python3.4/site-packages/django/template/response.py", line 158, in render
    self.content = self.rendered_content
  File "/home/guinsly/.pyenv/versions/django1.9.3.4.3/lib/python3.4/site-packages/django/template/response.py", line 135, in rendered_content
    content = template.render(context, self._request)
  File "/home/guinsly/.pyenv/versions/django1.9.3.4.3/lib/python3.4/site-packages/django/template/backends/django.py", line 74, in render
    return self.template.render(context)
  File "/home/guinsly/.pyenv/versions/django1.9.3.4.3/lib/python3.4/site-packages/django/template/base.py", line 210, in render
    return self._render(context)
  File "/home/guinsly/.pyenv/versions/django1.9.3.4.3/lib/python3.4/site-packages/django/test/utils.py", line 96, in instrumented_test_render
    return self.nodelist.render(context)
  File "/home/guinsly/.pyenv/versions/django1.9.3.4.3/lib/python3.4/site-packages/django/template/base.py", line 905, in render
    bit = self.render_node(node, context)
  File "/home/guinsly/.pyenv/versions/django1.9.3.4.3/lib/python3.4/site-packages/django/template/debug.py", line 79, in render_node
    return node.render(context)
  File "/home/guinsly/.pyenv/versions/django1.9.3.4.3/lib/python3.4/site-packages/django/template/loader_tags.py", line 135, in render
    return compiled_parent._render(context)
  File "/home/guinsly/.pyenv/versions/django1.9.3.4.3/lib/python3.4/site-packages/django/test/utils.py", line 96, in instrumented_test_render
    return self.nodelist.render(context)
  File "/home/guinsly/.pyenv/versions/django1.9.3.4.3/lib/python3.4/site-packages/django/template/base.py", line 905, in render
    bit = self.render_node(node, context)
  File "/home/guinsly/.pyenv/versions/django1.9.3.4.3/lib/python3.4/site-packages/django/template/debug.py", line 79, in render_node
    return node.render(context)
  File "/home/guinsly/.pyenv/versions/django1.9.3.4.3/lib/python3.4/site-packages/django/template/loader_tags.py", line 65, in render
    result = block.nodelist.render(context)
  File "/home/guinsly/.pyenv/versions/django1.9.3.4.3/lib/python3.4/site-packages/django/template/base.py", line 905, in render
    bit = self.render_node(node, context)
  File "/home/guinsly/.pyenv/versions/django1.9.3.4.3/lib/python3.4/site-packages/django/template/debug.py", line 79, in render_node
    return node.render(context)
  File "/home/guinsly/.pyenv/versions/django1.9.3.4.3/lib/python3.4/site-packages/django/template/defaulttags.py", line 329, in render
    return nodelist.render(context)
  File "/home/guinsly/.pyenv/versions/django1.9.3.4.3/lib/python3.4/site-packages/django/template/base.py", line 905, in render
    bit = self.render_node(node, context)
  File "/home/guinsly/.pyenv/versions/django1.9.3.4.3/lib/python3.4/site-packages/django/template/debug.py", line 79, in render_node
    return node.render(context)
  File "/home/guinsly/.pyenv/versions/django1.9.3.4.3/lib/python3.4/site-packages/django/template/defaulttags.py", line 507, in render
    six.reraise(*exc_info)
  File "/home/guinsly/.pyenv/versions/django1.9.3.4.3/lib/python3.4/site-packages/django/utils/six.py", line 686, in reraise
    raise value
  File "/home/guinsly/.pyenv/versions/django1.9.3.4.3/lib/python3.4/site-packages/django/template/defaulttags.py", line 493, in render
    url = reverse(view_name, args=args, kwargs=kwargs, current_app=current_app)
  File "/home/guinsly/.pyenv/versions/django1.9.3.4.3/lib/python3.4/site-packages/django/core/urlresolvers.py", line 578, in reverse
    return force_text(iri_to_uri(resolver._reverse_with_prefix(view, prefix, *args, **kwargs)))
  File "/home/guinsly/.pyenv/versions/django1.9.3.4.3/lib/python3.4/site-packages/django/core/urlresolvers.py", line 495, in _reverse_with_prefix
    (lookup_view_s, args, kwargs, len(patterns), patterns))
django.core.urlresolvers.NoReverseMatch: Reverse for 'register' with arguments '()' and keyword arguments '{}' not found. 0 pattern(s) tried: []
[2016-06-14 19:05:53,318] ERROR % : Internal Server Error: /account/login/
Traceback (most recent call last):
  File "/home/guinsly/.pyenv/versions/django1.9.3.4.3/lib/python3.4/site-packages/django/template/defaulttags.py", line 501, in render
    current_app=current_app)
  File "/home/guinsly/.pyenv/versions/django1.9.3.4.3/lib/python3.4/site-packages/django/core/urlresolvers.py", line 578, in reverse
    return force_text(iri_to_uri(resolver._reverse_with_prefix(view, prefix, *args, **kwargs)))
  File "/home/guinsly/.pyenv/versions/django1.9.3.4.3/lib/python3.4/site-packages/django/core/urlresolvers.py", line 495, in _reverse_with_prefix
    (lookup_view_s, args, kwargs, len(patterns), patterns))
django.core.urlresolvers.NoReverseMatch: Reverse for 'settings.register' with arguments '()' and keyword arguments '{}' not found. 0 pattern(s) tried: []

During handling of the above exception, another exception occurred:

Traceback (most recent call last):
  File "/home/guinsly/.pyenv/versions/django1.9.3.4.3/lib/python3.4/site-packages/django/core/handlers/base.py", line 164, in get_response
    response = response.render()
  File "/home/guinsly/.pyenv/versions/django1.9.3.4.3/lib/python3.4/site-packages/django/template/response.py", line 158, in render
    self.content = self.rendered_content
  File "/home/guinsly/.pyenv/versions/django1.9.3.4.3/lib/python3.4/site-packages/django/template/response.py", line 135, in rendered_content
    content = template.render(context, self._request)
  File "/home/guinsly/.pyenv/versions/django1.9.3.4.3/lib/python3.4/site-packages/django/template/backends/django.py", line 74, in render
    return self.template.render(context)
  File "/home/guinsly/.pyenv/versions/django1.9.3.4.3/lib/python3.4/site-packages/django/template/base.py", line 210, in render
    return self._render(context)
  File "/home/guinsly/.pyenv/versions/django1.9.3.4.3/lib/python3.4/site-packages/django/test/utils.py", line 96, in instrumented_test_render
    return self.nodelist.render(context)
  File "/home/guinsly/.pyenv/versions/django1.9.3.4.3/lib/python3.4/site-packages/django/template/base.py", line 905, in render
    bit = self.render_node(node, context)
  File "/home/guinsly/.pyenv/versions/django1.9.3.4.3/lib/python3.4/site-packages/django/template/debug.py", line 79, in render_node
    return node.render(context)
  File "/home/guinsly/.pyenv/versions/django1.9.3.4.3/lib/python3.4/site-packages/django/template/loader_tags.py", line 135, in render
    return compiled_parent._render(context)
  File "/home/guinsly/.pyenv/versions/django1.9.3.4.3/lib/python3.4/site-packages/django/test/utils.py", line 96, in instrumented_test_render
    return self.nodelist.render(context)
  File "/home/guinsly/.pyenv/versions/django1.9.3.4.3/lib/python3.4/site-packages/django/template/base.py", line 905, in render
    bit = self.render_node(node, context)
  File "/home/guinsly/.pyenv/versions/django1.9.3.4.3/lib/python3.4/site-packages/django/template/debug.py", line 79, in render_node
    return node.render(context)
  File "/home/guinsly/.pyenv/versions/django1.9.3.4.3/lib/python3.4/site-packages/django/template/loader_tags.py", line 65, in render
    result = block.nodelist.render(context)
  File "/home/guinsly/.pyenv/versions/django1.9.3.4.3/lib/python3.4/site-packages/django/template/base.py", line 905, in render
    bit = self.render_node(node, context)
  File "/home/guinsly/.pyenv/versions/django1.9.3.4.3/lib/python3.4/site-packages/django/template/debug.py", line 79, in render_node
    return node.render(context)
  File "/home/guinsly/.pyenv/versions/django1.9.3.4.3/lib/python3.4/site-packages/django/template/defaulttags.py", line 329, in render
    return nodelist.render(context)
  File "/home/guinsly/.pyenv/versions/django1.9.3.4.3/lib/python3.4/site-packages/django/template/base.py", line 905, in render
    bit = self.render_node(node, context)
  File "/home/guinsly/.pyenv/versions/django1.9.3.4.3/lib/python3.4/site-packages/django/template/debug.py", line 79, in render_node
    return node.render(context)
  File "/home/guinsly/.pyenv/versions/django1.9.3.4.3/lib/python3.4/site-packages/django/template/defaulttags.py", line 507, in render
    six.reraise(*exc_info)
  File "/home/guinsly/.pyenv/versions/django1.9.3.4.3/lib/python3.4/site-packages/django/utils/six.py", line 686, in reraise
    raise value
  File "/home/guinsly/.pyenv/versions/django1.9.3.4.3/lib/python3.4/site-packages/django/template/defaulttags.py", line 493, in render
    url = reverse(view_name, args=args, kwargs=kwargs, current_app=current_app)
  File "/home/guinsly/.pyenv/versions/django1.9.3.4.3/lib/python3.4/site-packages/django/core/urlresolvers.py", line 578, in reverse
    return force_text(iri_to_uri(resolver._reverse_with_prefix(view, prefix, *args, **kwargs)))
  File "/home/guinsly/.pyenv/versions/django1.9.3.4.3/lib/python3.4/site-packages/django/core/urlresolvers.py", line 495, in _reverse_with_prefix
    (lookup_view_s, args, kwargs, len(patterns), patterns))
django.core.urlresolvers.NoReverseMatch: Reverse for 'register' with arguments '()' and keyword arguments '{}' not found. 0 pattern(s) tried: []
[2016-06-14 19:06:26,076] ERROR % : Internal Server Error: /account/login/
Traceback (most recent call last):
  File "/home/guinsly/.pyenv/versions/django1.9.3.4.3/lib/python3.4/site-packages/django/template/defaulttags.py", line 501, in render
    current_app=current_app)
  File "/home/guinsly/.pyenv/versions/django1.9.3.4.3/lib/python3.4/site-packages/django/core/urlresolvers.py", line 578, in reverse
    return force_text(iri_to_uri(resolver._reverse_with_prefix(view, prefix, *args, **kwargs)))
  File "/home/guinsly/.pyenv/versions/django1.9.3.4.3/lib/python3.4/site-packages/django/core/urlresolvers.py", line 495, in _reverse_with_prefix
    (lookup_view_s, args, kwargs, len(patterns), patterns))
django.core.urlresolvers.NoReverseMatch: Reverse for 'settings.login' with arguments '()' and keyword arguments '{}' not found. 0 pattern(s) tried: []

During handling of the above exception, another exception occurred:

Traceback (most recent call last):
  File "/home/guinsly/.pyenv/versions/django1.9.3.4.3/lib/python3.4/site-packages/django/core/handlers/base.py", line 164, in get_response
    response = response.render()
  File "/home/guinsly/.pyenv/versions/django1.9.3.4.3/lib/python3.4/site-packages/django/template/response.py", line 158, in render
    self.content = self.rendered_content
  File "/home/guinsly/.pyenv/versions/django1.9.3.4.3/lib/python3.4/site-packages/django/template/response.py", line 135, in rendered_content
    content = template.render(context, self._request)
  File "/home/guinsly/.pyenv/versions/django1.9.3.4.3/lib/python3.4/site-packages/django/template/backends/django.py", line 74, in render
    return self.template.render(context)
  File "/home/guinsly/.pyenv/versions/django1.9.3.4.3/lib/python3.4/site-packages/django/template/base.py", line 210, in render
    return self._render(context)
  File "/home/guinsly/.pyenv/versions/django1.9.3.4.3/lib/python3.4/site-packages/django/test/utils.py", line 96, in instrumented_test_render
    return self.nodelist.render(context)
  File "/home/guinsly/.pyenv/versions/django1.9.3.4.3/lib/python3.4/site-packages/django/template/base.py", line 905, in render
    bit = self.render_node(node, context)
  File "/home/guinsly/.pyenv/versions/django1.9.3.4.3/lib/python3.4/site-packages/django/template/debug.py", line 79, in render_node
    return node.render(context)
  File "/home/guinsly/.pyenv/versions/django1.9.3.4.3/lib/python3.4/site-packages/django/template/loader_tags.py", line 135, in render
    return compiled_parent._render(context)
  File "/home/guinsly/.pyenv/versions/django1.9.3.4.3/lib/python3.4/site-packages/django/test/utils.py", line 96, in instrumented_test_render
    return self.nodelist.render(context)
  File "/home/guinsly/.pyenv/versions/django1.9.3.4.3/lib/python3.4/site-packages/django/template/base.py", line 905, in render
    bit = self.render_node(node, context)
  File "/home/guinsly/.pyenv/versions/django1.9.3.4.3/lib/python3.4/site-packages/django/template/debug.py", line 79, in render_node
    return node.render(context)
  File "/home/guinsly/.pyenv/versions/django1.9.3.4.3/lib/python3.4/site-packages/django/template/loader_tags.py", line 65, in render
    result = block.nodelist.render(context)
  File "/home/guinsly/.pyenv/versions/django1.9.3.4.3/lib/python3.4/site-packages/django/template/base.py", line 905, in render
    bit = self.render_node(node, context)
  File "/home/guinsly/.pyenv/versions/django1.9.3.4.3/lib/python3.4/site-packages/django/template/debug.py", line 79, in render_node
    return node.render(context)
  File "/home/guinsly/.pyenv/versions/django1.9.3.4.3/lib/python3.4/site-packages/django/template/defaulttags.py", line 507, in render
    six.reraise(*exc_info)
  File "/home/guinsly/.pyenv/versions/django1.9.3.4.3/lib/python3.4/site-packages/django/utils/six.py", line 686, in reraise
    raise value
  File "/home/guinsly/.pyenv/versions/django1.9.3.4.3/lib/python3.4/site-packages/django/template/defaulttags.py", line 493, in render
    url = reverse(view_name, args=args, kwargs=kwargs, current_app=current_app)
  File "/home/guinsly/.pyenv/versions/django1.9.3.4.3/lib/python3.4/site-packages/django/core/urlresolvers.py", line 578, in reverse
    return force_text(iri_to_uri(resolver._reverse_with_prefix(view, prefix, *args, **kwargs)))
  File "/home/guinsly/.pyenv/versions/django1.9.3.4.3/lib/python3.4/site-packages/django/core/urlresolvers.py", line 495, in _reverse_with_prefix
    (lookup_view_s, args, kwargs, len(patterns), patterns))
django.core.urlresolvers.NoReverseMatch: Reverse for 'login' with arguments '()' and keyword arguments '{}' not found. 0 pattern(s) tried: []
[2016-06-14 19:06:54,569] ERROR % : Internal Server Error: /account/login/
Traceback (most recent call last):
  File "/home/guinsly/.pyenv/versions/django1.9.3.4.3/lib/python3.4/site-packages/django/template/defaulttags.py", line 501, in render
    current_app=current_app)
  File "/home/guinsly/.pyenv/versions/django1.9.3.4.3/lib/python3.4/site-packages/django/core/urlresolvers.py", line 578, in reverse
    return force_text(iri_to_uri(resolver._reverse_with_prefix(view, prefix, *args, **kwargs)))
  File "/home/guinsly/.pyenv/versions/django1.9.3.4.3/lib/python3.4/site-packages/django/core/urlresolvers.py", line 495, in _reverse_with_prefix
    (lookup_view_s, args, kwargs, len(patterns), patterns))
django.core.urlresolvers.NoReverseMatch: Reverse for 'settings.password_reset' with arguments '()' and keyword arguments '{}' not found. 0 pattern(s) tried: []

During handling of the above exception, another exception occurred:

Traceback (most recent call last):
  File "/home/guinsly/.pyenv/versions/django1.9.3.4.3/lib/python3.4/site-packages/django/core/handlers/base.py", line 164, in get_response
    response = response.render()
  File "/home/guinsly/.pyenv/versions/django1.9.3.4.3/lib/python3.4/site-packages/django/template/response.py", line 158, in render
    self.content = self.rendered_content
  File "/home/guinsly/.pyenv/versions/django1.9.3.4.3/lib/python3.4/site-packages/django/template/response.py", line 135, in rendered_content
    content = template.render(context, self._request)
  File "/home/guinsly/.pyenv/versions/django1.9.3.4.3/lib/python3.4/site-packages/django/template/backends/django.py", line 74, in render
    return self.template.render(context)
  File "/home/guinsly/.pyenv/versions/django1.9.3.4.3/lib/python3.4/site-packages/django/template/base.py", line 210, in render
    return self._render(context)
  File "/home/guinsly/.pyenv/versions/django1.9.3.4.3/lib/python3.4/site-packages/django/test/utils.py", line 96, in instrumented_test_render
    return self.nodelist.render(context)
  File "/home/guinsly/.pyenv/versions/django1.9.3.4.3/lib/python3.4/site-packages/django/template/base.py", line 905, in render
    bit = self.render_node(node, context)
  File "/home/guinsly/.pyenv/versions/django1.9.3.4.3/lib/python3.4/site-packages/django/template/debug.py", line 79, in render_node
    return node.render(context)
  File "/home/guinsly/.pyenv/versions/django1.9.3.4.3/lib/python3.4/site-packages/django/template/loader_tags.py", line 135, in render
    return compiled_parent._render(context)
  File "/home/guinsly/.pyenv/versions/django1.9.3.4.3/lib/python3.4/site-packages/django/test/utils.py", line 96, in instrumented_test_render
    return self.nodelist.render(context)
  File "/home/guinsly/.pyenv/versions/django1.9.3.4.3/lib/python3.4/site-packages/django/template/base.py", line 905, in render
    bit = self.render_node(node, context)
  File "/home/guinsly/.pyenv/versions/django1.9.3.4.3/lib/python3.4/site-packages/django/template/debug.py", line 79, in render_node
    return node.render(context)
  File "/home/guinsly/.pyenv/versions/django1.9.3.4.3/lib/python3.4/site-packages/django/template/loader_tags.py", line 65, in render
    result = block.nodelist.render(context)
  File "/home/guinsly/.pyenv/versions/django1.9.3.4.3/lib/python3.4/site-packages/django/template/base.py", line 905, in render
    bit = self.render_node(node, context)
  File "/home/guinsly/.pyenv/versions/django1.9.3.4.3/lib/python3.4/site-packages/django/template/debug.py", line 79, in render_node
    return node.render(context)
  File "/home/guinsly/.pyenv/versions/django1.9.3.4.3/lib/python3.4/site-packages/django/template/defaulttags.py", line 507, in render
    six.reraise(*exc_info)
  File "/home/guinsly/.pyenv/versions/django1.9.3.4.3/lib/python3.4/site-packages/django/utils/six.py", line 686, in reraise
    raise value
  File "/home/guinsly/.pyenv/versions/django1.9.3.4.3/lib/python3.4/site-packages/django/template/defaulttags.py", line 493, in render
    url = reverse(view_name, args=args, kwargs=kwargs, current_app=current_app)
  File "/home/guinsly/.pyenv/versions/django1.9.3.4.3/lib/python3.4/site-packages/django/core/urlresolvers.py", line 578, in reverse
    return force_text(iri_to_uri(resolver._reverse_with_prefix(view, prefix, *args, **kwargs)))
  File "/home/guinsly/.pyenv/versions/django1.9.3.4.3/lib/python3.4/site-packages/django/core/urlresolvers.py", line 495, in _reverse_with_prefix
    (lookup_view_s, args, kwargs, len(patterns), patterns))
django.core.urlresolvers.NoReverseMatch: Reverse for 'password_reset' with arguments '()' and keyword arguments '{}' not found. 0 pattern(s) tried: []
[2016-06-14 19:09:24,925] ERROR % : Internal Server Error: /account/login/
Traceback (most recent call last):
  File "/home/guinsly/.pyenv/versions/django1.9.3.4.3/lib/python3.4/site-packages/django/core/urlresolvers.py", line 564, in reverse
    extra, resolver = resolver.namespace_dict[ns]
KeyError: 'settings.social'

During handling of the above exception, another exception occurred:

Traceback (most recent call last):
  File "/home/guinsly/.pyenv/versions/django1.9.3.4.3/lib/python3.4/site-packages/django/template/defaulttags.py", line 501, in render
    current_app=current_app)
  File "/home/guinsly/.pyenv/versions/django1.9.3.4.3/lib/python3.4/site-packages/django/core/urlresolvers.py", line 574, in reverse
    key)
django.core.urlresolvers.NoReverseMatch: 'settings.social' is not a registered namespace

During handling of the above exception, another exception occurred:

Traceback (most recent call last):
  File "/home/guinsly/.pyenv/versions/django1.9.3.4.3/lib/python3.4/site-packages/django/core/handlers/base.py", line 164, in get_response
    response = response.render()
  File "/home/guinsly/.pyenv/versions/django1.9.3.4.3/lib/python3.4/site-packages/django/template/response.py", line 158, in render
    self.content = self.rendered_content
  File "/home/guinsly/.pyenv/versions/django1.9.3.4.3/lib/python3.4/site-packages/django/template/response.py", line 135, in rendered_content
    content = template.render(context, self._request)
  File "/home/guinsly/.pyenv/versions/django1.9.3.4.3/lib/python3.4/site-packages/django/template/backends/django.py", line 74, in render
    return self.template.render(context)
  File "/home/guinsly/.pyenv/versions/django1.9.3.4.3/lib/python3.4/site-packages/django/template/base.py", line 210, in render
    return self._render(context)
  File "/home/guinsly/.pyenv/versions/django1.9.3.4.3/lib/python3.4/site-packages/django/test/utils.py", line 96, in instrumented_test_render
    return self.nodelist.render(context)
  File "/home/guinsly/.pyenv/versions/django1.9.3.4.3/lib/python3.4/site-packages/django/template/base.py", line 905, in render
    bit = self.render_node(node, context)
  File "/home/guinsly/.pyenv/versions/django1.9.3.4.3/lib/python3.4/site-packages/django/template/debug.py", line 79, in render_node
    return node.render(context)
  File "/home/guinsly/.pyenv/versions/django1.9.3.4.3/lib/python3.4/site-packages/django/template/loader_tags.py", line 135, in render
    return compiled_parent._render(context)
  File "/home/guinsly/.pyenv/versions/django1.9.3.4.3/lib/python3.4/site-packages/django/test/utils.py", line 96, in instrumented_test_render
    return self.nodelist.render(context)
  File "/home/guinsly/.pyenv/versions/django1.9.3.4.3/lib/python3.4/site-packages/django/template/base.py", line 905, in render
    bit = self.render_node(node, context)
  File "/home/guinsly/.pyenv/versions/django1.9.3.4.3/lib/python3.4/site-packages/django/template/debug.py", line 79, in render_node
    return node.render(context)
  File "/home/guinsly/.pyenv/versions/django1.9.3.4.3/lib/python3.4/site-packages/django/template/loader_tags.py", line 65, in render
    result = block.nodelist.render(context)
  File "/home/guinsly/.pyenv/versions/django1.9.3.4.3/lib/python3.4/site-packages/django/template/base.py", line 905, in render
    bit = self.render_node(node, context)
  File "/home/guinsly/.pyenv/versions/django1.9.3.4.3/lib/python3.4/site-packages/django/template/debug.py", line 79, in render_node
    return node.render(context)
  File "/home/guinsly/.pyenv/versions/django1.9.3.4.3/lib/python3.4/site-packages/django/template/defaulttags.py", line 507, in render
    six.reraise(*exc_info)
  File "/home/guinsly/.pyenv/versions/django1.9.3.4.3/lib/python3.4/site-packages/django/utils/six.py", line 686, in reraise
    raise value
  File "/home/guinsly/.pyenv/versions/django1.9.3.4.3/lib/python3.4/site-packages/django/template/defaulttags.py", line 493, in render
    url = reverse(view_name, args=args, kwargs=kwargs, current_app=current_app)
  File "/home/guinsly/.pyenv/versions/django1.9.3.4.3/lib/python3.4/site-packages/django/core/urlresolvers.py", line 574, in reverse
    key)
django.core.urlresolvers.NoReverseMatch: 'social' is not a registered namespace
[2016-06-14 19:10:48,609] WARNING % : Not Found: /social-auth/login/facebook/
